<?xml version="1.0" encoding="UTF-8" ?>
<robot xmlns:xacro="http://www.ros.org/wiki/xacro" name="mycobot">
    <xacro:property name="width" value=".2" />
    <material name="white">
        <color rgba="0.9 0.9 0.9 1" />
    </material>
    <link name="base_mount" />
    <link name="joint1">
        <visual>
            <geometry>
                <mesh filename="package://mycobot_description/meshes/joint1.dae" />
            </geometry>
            <origin xyz="0.0 0 0 " rpy=" 0 0 0" />
        </visual>
    </link>
    <link name="joint2">
        <visual>
            <geometry>
                <mesh filename="package://mycobot_description/meshes/joint2.dae" />
            </geometry>
            <origin xyz="0.0 0 0 " rpy=" 0 0 0" />
        </visual>
    </link>
    <link name="joint3">
        <visual>
            <geometry>
                <mesh filename="package://mycobot_description/meshes/joint3.dae" />
            </geometry>
            <origin xyz="0.0 0 0 " rpy=" 0 0 0" />
        </visual>
    </link>
    <link name="joint4">
        <visual>
            <geometry>
                <mesh filename="package://mycobot_description/meshes/joint4.dae" />
            </geometry>
            <origin xyz="0.0 0 0 " rpy=" 0 0 0" />
        </visual>
    </link>
    <link name="joint5">
        <visual>
            <geometry>
                <mesh filename="package://mycobot_description/meshes/joint5.dae" />
            </geometry>
            <origin xyz="0.0 0 0 " rpy=" 0 0 0" />
        </visual>
    </link>
    <link name="joint6">
        <visual>
            <geometry>
                <mesh filename="package://mycobot_description/meshes/joint6.dae" />
            </geometry>
            <origin xyz="0.0 0 0 " rpy=" 0 0 0" />
        </visual>
    </link>
    <link name="joint6_flange">
        <visual>
            <geometry>
                <cylinder length="0.014" radius="0.019" />
            </geometry>
            <origin xyz="0.0 0 0 " rpy=" 1.57075 0 0" />
            <material name="white" />
        </visual>
    </link>
    <link name="gripper_base">
        <visual>
            <geometry>
                <mesh filename="package://mycobot_description/meshes/gripper_base.stl" scale="0.001 0.001 0.001" />
            </geometry>
            <origin xyz="0.0 0 0 " rpy=" 0 0 0" />
            <material name="white" />
        </visual>
    </link>
    <link name="finger_right">
        <visual>
            <geometry>
                <mesh filename="package://mycobot_description/meshes/finger_right.stl" scale="0.001 0.001 0.001" />
            </geometry>
            <origin xyz="0.0 0 0 " rpy=" 0 0 0" />
            <material name="white" />
        </visual>
    </link>
    <link name="finger_left">
        <visual>
            <geometry>
                <mesh filename="package://mycobot_description/meshes/finger_left.stl" scale="0.001 0.001 0.001" />
            </geometry>
            <origin xyz="0.0 0 0 " rpy=" 0 0 0" />
            <material name="white" />
        </visual>
    </link>
    <link name="tool0" />
    <joint name="base_mount_to_joint1" type="fixed">
        <axis xyz="0 0 1" />
        <parent link="base_mount" />
        <child link="joint1" />
        <origin xyz="0 0 0.005" rpy="0 0 -1.5708" />
    </joint>
    <joint name="joint2_to_joint1" type="revolute">
        <axis xyz="0 0 1" />
        <limit effort="1000.0" lower="-3.14" upper="3.14159" velocity="0" />
        <parent link="joint1" />
        <child link="joint2" />
        <origin xyz="0 0 0.0706" rpy="0 0 0" />
    </joint>
    <joint name="joint3_to_joint2" type="revolute">
        <axis xyz="1 0 0" />
        <limit effort="1000.0" lower="-3.14" upper="3.14159" velocity="0" />
        <parent link="joint2" />
        <child link="joint3" />
        <origin xyz="0.03256 0  0.05976" rpy="0 0 0" />
    </joint>
    <joint name="joint4_to_joint3" type="revolute">
        <axis xyz="1 0 0" />
        <limit effort="1000.0" lower="-3.14" upper="3.14159" velocity="0" />
        <parent link="joint3" />
        <child link="joint4" />
        <origin xyz=" 0.00272 0 0.1104   " rpy="0 0 0" />
    </joint>
    <joint name="joint5_to_joint4" type="revolute">
        <axis xyz="1 0 0" />
        <limit effort="1000.0" lower="-3.14" upper="3.14159" velocity="0" />
        <parent link="joint4" />
        <child link="joint5" />
        <origin xyz="-0.00164 0 0.096" rpy="0 0 0" />
    </joint>
    <joint name="joint6_to_joint5" type="revolute">
        <axis xyz="0 0 1" />
        <limit effort="1000.0" lower="-3.14" upper="3.14159" velocity="0" />
        <parent link="joint5" />
        <child link="joint6" />
        <origin xyz="0.0288 0 0.02976" rpy="0 0 0" />
    </joint>
    <joint name="joint6output_to_joint6" type="revolute">
        <axis xyz="0 1  0" />
        <limit effort="1000.0" lower="-3.14" upper="3.14159" velocity="0" />
        <parent link="joint6" />
        <child link="joint6_flange" />
        <origin xyz="0 0.0526 0.03792 " rpy="0 0 0" />
    </joint>
    <joint name="end_to_gripper_base" type="fixed">
        <axis xyz="0 0 1" />
        <parent link="joint6_flange" />
        <child link="gripper_base" />
        <origin xyz="0 0.007 0" rpy="0 0 1.5708" />
    </joint>
    <joint name="gripper_base_to_r_finger" type="prismatic">
        <mimic joint="gripper_base_to_l_finger" multiplier="-1" />
        <limit lower="-0.018" upper="0" effort="1.0" velocity="0" />
        <axis xyz="0 1 0" />
        <parent link="gripper_base" />
        <child link="finger_right" />
        <origin xyz="0.033 0 0" rpy="0 0 0" />
    </joint>
    <joint name="gripper_base_to_l_finger" type="prismatic">
        <limit lower="0" upper="0.018" effort="1.0" velocity="0" />
        <axis xyz="0 1 0" />
        <parent link="gripper_base" />
        <child link="finger_left" />
        <origin xyz="0.033 0 0" rpy="0 0 0" />
    </joint>
    <joint name="ee_to_tool0" type="fixed">
        <parent link="joint6_flange" />
        <child link="tool0" />
        <origin xyz="0 0.062 0" rpy="0 0 1.5708" />
    </joint>
    
<transmission name="trans_joint2_to_joint1">
        <type>transmission_interface/SimpleTransmission</type>
        <joint name="joint2_to_joint1">
            <hardwareInterface>hardware_interface/EffortJointInterface</hardwareInterface>
        </joint>
        <actuator name="joint2_to_joint1_motor">
            <hardwareInterface>hardware_interface/EffortJointInterface</hardwareInterface>
            <mechanicalReduction>1</mechanicalReduction>
        </actuator>
    </transmission>
    <transmission name="trans_joint3_to_joint2">
        <type>transmission_interface/SimpleTransmission</type>
        <joint name="joint3_to_joint2">
            <hardwareInterface>hardware_interface/EffortJointInterface</hardwareInterface>
        </joint>
        <actuator name="joint3_to_joint2_motor">
            <hardwareInterface>hardware_interface/EffortJointInterface</hardwareInterface>
            <mechanicalReduction>1</mechanicalReduction>
        </actuator>
    </transmission>
    <transmission name="trans_joint4_to_joint3">
        <type>transmission_interface/SimpleTransmission</type>
        <joint name="joint4_to_joint3">
            <hardwareInterface>hardware_interface/EffortJointInterface</hardwareInterface>
        </joint>
        <actuator name="joint4_to_joint3_motor">
            <hardwareInterface>hardware_interface/EffortJointInterface</hardwareInterface>
            <mechanicalReduction>1</mechanicalReduction>
        </actuator>
    </transmission>
    <transmission name="trans_joint5_to_joint4">
        <type>transmission_interface/SimpleTransmission</type>
        <joint name="joint5_to_joint4">
            <hardwareInterface>hardware_interface/EffortJointInterface</hardwareInterface>
        </joint>
        <actuator name="joint5_to_joint4_motor">
            <hardwareInterface>hardware_interface/EffortJointInterface</hardwareInterface>
            <mechanicalReduction>1</mechanicalReduction>
        </actuator>
    </transmission>
    <transmission name="trans_joint6_to_joint5">
        <type>transmission_interface/SimpleTransmission</type>
        <joint name="joint6_to_joint5">
            <hardwareInterface>hardware_interface/EffortJointInterface</hardwareInterface>
        </joint>
        <actuator name="joint6_to_joint5_motor">
            <hardwareInterface>hardware_interface/EffortJointInterface</hardwareInterface>
            <mechanicalReduction>1</mechanicalReduction>
        </actuator>
    </transmission>
    <transmission name="trans_joint6output_to_joint6">
        <type>transmission_interface/SimpleTransmission</type>
        <joint name="joint6output_to_joint6">
            <hardwareInterface>hardware_interface/EffortJointInterface</hardwareInterface>
        </joint>
        <actuator name="joint6output_to_joint6_motor">
            <hardwareInterface>hardware_interface/EffortJointInterface</hardwareInterface>
            <mechanicalReduction>1</mechanicalReduction>
        </actuator>
    </transmission>
    <transmission name="trans_gripper_base_to_r_finger">
        <type>transmission_interface/SimpleTransmission</type>
        <joint name="gripper_base_to_r_finger">
            <hardwareInterface>hardware_interface/EffortJointInterface</hardwareInterface>
        </joint>
        <actuator name="gripper_base_to_r_finger_motor">
            <hardwareInterface>hardware_interface/EffortJointInterface</hardwareInterface>
            <mechanicalReduction>1</mechanicalReduction>
        </actuator>
    </transmission>
    <transmission name="trans_gripper_base_to_l_finger">
        <type>transmission_interface/SimpleTransmission</type>
        <joint name="gripper_base_to_l_finger">
            <hardwareInterface>hardware_interface/EffortJointInterface</hardwareInterface>
        </joint>
        <actuator name="gripper_base_to_l_finger_motor">
            <hardwareInterface>hardware_interface/EffortJointInterface</hardwareInterface>
            <mechanicalReduction>1</mechanicalReduction>
        </actuator>
    </transmission>
    <gazebo>
        <plugin name="gazebo_ros_control" filename="libgazebo_ros_control.so">
            <robotNamespace>/</robotNamespace>
        </plugin>
    </gazebo>
</robot>